<?xml version="1.0" ?>

<robot name="robot">

    <!-- =========================================================================================================== -->

    <!-- Link - chassis -->
    <link name="base_link">
        <inertial>
            <mass value="10" />
            <origin xyz="0 0 0" rpy="0 0 0" />
            <inertia ixx="1.5417" ixy="0" ixz="0" iyy="3.467" iyz="0" izz="4.742" />
        </inertial>
        
        <collision>
            <geometry>
                <cylinder radius="0.25" length="0.3" />
            </geometry>
        </collision>

        <visual>
            <geometry>
                <cylinder radius="0.25" length="0.3" />
            </geometry>
            <material name="DarkBlue">
                <color rgba="0.2 0.2 0.4 1" />
            </material>
        </visual>
    </link>

    <!-- =========================================================================================================== -->

    <!-- Joint - Front Caster wheel -->
    <joint name="joint_front_chassis_caster_wheel" type="fixed">
        <origin rpy="0 0 0" xyz="0.1 0.0 -0.15" />
        <child link="link_front_caster_wheel" />
        <parent link="base_link" />
        <joint_properties damping="1.0" friction="0.0" />
    </joint>

    <!-- Link - Front Caster wheel -->
    <link name="link_front_caster_wheel">
        <inertial>
            <mass value="1" />
            <origin xyz="0.1 0.0 -0.15" rpy="0 0 0" />
            <inertia ixx="0.002526666666667" ixy="0" ixz="0" iyy="0.002526666666667" iyz="0" izz="0.005"/>
        </inertial>

        <!-- Front wheel support -->
        <collision>
            <origin rpy="0 0 0" xyz="0 0 0" />
            <geometry>
                <sphere radius="0.025" />
            </geometry>
        </collision>
        <visual>
            <origin rpy="0 0 0" xyz="0 0 0" />
            <geometry>
                <sphere radius="0.025" />
            </geometry>
            <material name="DarkBlue">
                <color rgba="0.2 0.2 0.4 1" />
            </material>
        </visual>

        <!-- Front Caster wheel -->
        <collision>
            <origin rpy="0 0 0" xyz="0 0 -0.02" />
            <geometry>
                <sphere radius="0.010" />
            </geometry>
        </collision>
        <visual>
            <origin rpy="0 0 0" xyz="0 0 -0.02" />
            <geometry>
                <sphere radius="0.010" />
            </geometry>
            <material name="Grey">
                <color rgba="0.6 0.6 0.6 1" />
            </material>
        </visual>
    </link>

    <!-- =========================================================================================================== -->

    <!-- Joint - Back caster wheel -->
    <joint name="joint_back_chassis_caster_wheel" type="fixed">
        <origin rpy="0 0 0" xyz="-0.1 0.0 -0.15" />
        <child link="link_back_caster_wheel" />
        <parent link="base_link" />
        <joint_properties damping="1.0" friction="1.0" />
    </joint>

    <!-- Link - Back Caster Wheel -->
    <link name="link_back_caster_wheel">
        <inertial>
            <mass value="1" />
            <origin xyz="-0.1 0.0 -0.15" rpy="0 0 0" />
            <inertia ixx="0.002526666666667" ixy="0" ixz="0" iyy="0.002526666666667" iyz="0" izz="0.005"/>
        </inertial>

        <!-- Back wheel support -->
        <collision>
            <origin rpy="0 0 0" xyz="0 0 0" />
            <geometry>
                <sphere radius="0.025" />
            </geometry>
        </collision>
        <visual>
            <origin rpy="0 0 0" xyz="0 0 0" />
            <geometry>
                <sphere radius="0.025" />
            </geometry>
            <material name="DarkBlue">
                <color rgba="0.2 0.2 0.4 1" />
            </material>
        </visual>

        <!-- Back Caster wheel -->
        <collision>
            <origin rpy="0 0 0" xyz="0 0 -0.02" />
            <geometry>
                <sphere radius="0.010" />
            </geometry>
        </collision>
        <visual>
            <origin rpy="0 0 0" xyz="0 0 -0.02" />
            <geometry>
                <sphere radius="0.010" />
            </geometry>
            <material name="Grey">
                <color rgba="0.6 0.6 0.6 1" />
            </material>
        </visual>
    </link>

    <!-- =========================================================================================================== -->

    <!-- Joint - chassis / left wheel -->
    <joint name="joint_chassis_left_wheel" type="continuous">
        <origin rpy="0 0 0" xyz="0.0 0.2 -0.15" />
        <child link="link_left_wheel" />
        <parent link="base_link" />
        <axis rpy="0 0 0" xyz="0 1 0" />
        <limit effort="10000" velocity="1000" />
        <joint_properties damping="1.0" friction="0.0" />
    </joint>
    <!-- Link - left wheel -->
    <link name="link_left_wheel">
        <inertial>
            <mass value="1" />
            <origin xyz="0.0 0.2 -0.15" rpy="0 0 0" />
            <inertia ixx="0.002526666666667" ixy="0" ixz="0" iyy="0.002526666666667" iyz="0" izz="0.005"/>
        </inertial>

        <!-- Tires -->
        <collision>
            <origin rpy="1.5707 0 0" xyz="0 0 0" />
            <geometry>
                <cylinder length="0.03" radius="0.025"/>
            </geometry>
        </collision>
        <visual>
            <origin rpy="1.5707 0 0" xyz="0 0 0" />
            <geometry>
                <cylinder length="0.03" radius="0.025"/>
            </geometry>
            <material name="red">
                <color rgba="1 0.0 0.0 1" />
            </material>
        </visual>

    </link>

    <!-- =========================================================================================================== -->

    <!-- Joint - chassis / right wheel -->
    <joint name="joint_chassis_right_wheel" type="continuous">
        <origin rpy="0 0 0" xyz="0.0 -0.2 -0.15" />
        <child link="link_right_wheel" />
        <parent link="base_link" />
        <axis rpy="0 0 0" xyz="0 1 0" />
        <limit effort="10000" velocity="1000" />
        <joint_properties damping="1.0" friction="0.0" />
    </joint>
    <!-- Link - right wheel -->
    <link name="link_right_wheel">
        <inertial>
            <mass value="1" />
            <origin xyz="0.0 -0.2 -0.15" rpy="0 0 0" />
            <inertia ixx="0.002526666666667" ixy="0" ixz="0" iyy="0.002526666666667" iyz="0" izz="0.005"/>
        </inertial>

        <!-- Tires -->
        <collision>
            <origin rpy="1.5707 0 0" xyz="0 0 0" />
            <geometry>
                <cylinder length="0.03" radius="0.025"/>
            </geometry>
        </collision>
        <visual>
            <origin rpy="1.5707 0 0" xyz="0 0 0" />
            <geometry>
                <cylinder length="0.03" radius="0.025"/>
            </geometry>
            <material name="red">
                <color rgba="1 0.0 0.0 1" />
            </material>
        </visual>

    </link>
</robot>

<!-- =========================================================================================================== -->
